<log>
  <section name='Section with rescue'>
    <comment>
      This section will terminate because of the failure.
    </comment>
    <rescued_exception timestamp='2018-03-27-Tue-11.05.04.732' class='RuntimeError'>
      <message>
        This exception will be rescued and logged.
      </message>
      <backtrace>
        <![CDATA[
C:/Users/Burdette/Documents/GitHub/structured_log/readme_files/scripts/rescue.rb:6:in `block (2 levels) in <main>'
C:/Ruby22/lib/ruby/gems/2.2.0/gems/structured_log-0.1.0/lib/structured_log.rb:59:in `block in section'
C:/Ruby22/lib/ruby/gems/2.2.0/gems/structured_log-0.1.0/lib/structured_log.rb:117:in `put_element'
C:/Ruby22/lib/ruby/gems/2.2.0/gems/structured_log-0.1.0/lib/structured_log.rb:58:in `section'
C:/Users/Burdette/Documents/GitHub/structured_log/readme_files/scripts/rescue.rb:4:in `block in <main>'
C:/Ruby22/lib/ruby/gems/2.2.0/gems/structured_log-0.1.0/lib/structured_log.rb:39:in `open'
C:/Users/Burdette/Documents/GitHub/structured_log/readme_files/scripts/rescue.rb:3:in `<main>'
]]>
      </backtrace>
    </rescued_exception>
  </section>
  <section name='Another section'>
    <comment>
      This comment will be reached and logged, because of rescue above.
    </comment>
  </section>
</log>
