<log>
  <section name='Section with timestamp' timestamp='2018-03-24-Sat-08.03.25.149'>
    <uncaught_exception timestamp='2018-03-24-Sat-08.03.25.164' class='ArgumentError'>
      <message>
        wrong number of arguments (1 for 2)
      </message>
      <backtrace>
        <![CDATA[
C:/Ruby22/lib/ruby/gems/2.2.0/gems/structured_log-0.1.0/lib/structured_log.rb:64:in `comment'
C:/Users/Burdette/Documents/GitHub/structured_log/readme_files/scripts/time.rb:5:in `block (2 levels) in <main>'
C:/Ruby22/lib/ruby/gems/2.2.0/gems/structured_log-0.1.0/lib/structured_log.rb:59:in `block in section'
C:/Ruby22/lib/ruby/gems/2.2.0/gems/structured_log-0.1.0/lib/structured_log.rb:127:in `put_element'
C:/Ruby22/lib/ruby/gems/2.2.0/gems/structured_log-0.1.0/lib/structured_log.rb:58:in `section'
C:/Users/Burdette/Documents/GitHub/structured_log/readme_files/scripts/time.rb:4:in `block in <main>'
C:/Ruby22/lib/ruby/gems/2.2.0/gems/structured_log-0.1.0/lib/structured_log.rb:39:in `open'
C:/Users/Burdette/Documents/GitHub/structured_log/readme_files/scripts/time.rb:3:in `<main>'
]]>
      </backtrace>
    </uncaught_exception>
  </section>
</log>
