<log>
  <section name='Section with rescue'>
    <uncaught_exception>
      <class>
        RuntimeError
      </class>
      <message>
        Boo!
      </message>
      <backtrace>
        <![CDATA[
rescue.rb:5:in `block (2 levels) in <main>'
rescue.rb:4:in `block in <main>'
rescue.rb:3:in `<main>']]>
      </backtrace>
    </uncaught_exception>
  </section>
  <section name='Another section'>
    <comment>
      This section is ok.
    </comment>
  </section>
</log>
